{
 "cells": [
  {
   "cell_type": "markdown",
   "id": "90f37d80",
   "metadata": {},
   "source": [
    "# Derrik Pollock "
   ]
  },
  {
   "cell_type": "markdown",
   "id": "045eed55",
   "metadata": {},
   "source": [
    "## Final Project: Who's That Pokemon"
   ]
  },
  {
   "cell_type": "markdown",
   "id": "6d0beefb",
   "metadata": {},
   "source": [
    "The program first creates a machine learning model and trains the model with the specified data set containing hundreds of generation 1 Pokemon images."
   ]
  },
  {
   "cell_type": "markdown",
   "id": "55245125",
   "metadata": {},
   "source": [
    "### Initially, the model was trained using a smaller data set of 5 popular pok√©mon"
   ]
  },
  {
   "cell_type": "markdown",
   "id": "f14ee767",
   "metadata": {},
   "source": [
    "In order to preserve resources and simplify explanation...\n"
   ]
  },
  {
   "cell_type": "markdown",
   "id": "2847f6d9",
   "metadata": {},
   "source": [
    "### However, I personally have about 20 gpus spread throughout my house that can provide the processing power needed to train this model quickly"
   ]
  },
  {
   "cell_type": "code",
   "execution_count": 2,
   "id": "d9d7a12d",
   "metadata": {},
   "outputs": [
    {
     "data": {
      "text/plain": [
       "\" Who's that Pokemon?\\n\\tHere we write a machine learning program to classify pictures of Pokemon.\\n\\tWe use machine learning python libraries including TensorFlow and Keras.\\n\\tResults will typically be displayed in Plotly and Matplotlib.\\n\\tWritten by Shaun Miller using the Kaggle dataset https://www.kaggle.com/thedagger/pokemon-generation-one.\\n\\tThis program follows some of the tutorial from the TensorFlow website: https://www.tensorflow.org/tutorials/images/classification.\\n\""
      ]
     },
     "execution_count": 2,
     "metadata": {},
     "output_type": "execute_result"
    }
   ],
   "source": [
    "\"\"\" Who's that Pokemon?\n",
    "\tHere we write a machine learning program to classify pictures of Pokemon.\n",
    "\tWe use machine learning python libraries including TensorFlow and Keras.\n",
    "\tResults will typically be displayed in Plotly and Matplotlib.\n",
    "\tWritten by Shaun Miller using the Kaggle dataset https://www.kaggle.com/thedagger/pokemon-generation-one.\n",
    "\tThis program follows some of the tutorial from the TensorFlow website: https://www.tensorflow.org/tutorials/images/classification.\n",
    "\"\"\""
   ]
  },
  {
   "cell_type": "markdown",
   "id": "d691f36c",
   "metadata": {},
   "source": [
    "First, we import the necessary libraries"
   ]
  },
  {
   "cell_type": "code",
   "execution_count": 3,
   "id": "f70394f4",
   "metadata": {},
   "outputs": [],
   "source": [
    "import matplotlib.pyplot as plt\n",
    "import numpy as np\n",
    "import os\n",
    "from PIL import Image\n",
    "from PIL import ImageFont\n",
    "from PIL import ImageDraw\n",
    "import pathlib\n",
    "import sys\n",
    "\n",
    "import tensorflow as tf\n",
    "os.environ['TF_CPP_MIN_LOG_LEVEL'] = '3' #silence some of the tf warnings\n",
    "\n",
    "from tensorflow import keras\n",
    "from tensorflow.keras import layers\n",
    "from tensorflow.keras.models import Sequential"
   ]
  },
  {
   "cell_type": "markdown",
   "id": "1995f2cc",
   "metadata": {},
   "source": [
    "Then, we download and explore the dataset"
   ]
  },
  {
   "cell_type": "code",
   "execution_count": 4,
   "id": "0b6cb5b3",
   "metadata": {},
   "outputs": [],
   "source": [
    "def get_local_data(file_path, val_split=0.2, batch_size = 32, height = 180, width = 180):\n",
    "\t#returns training and validation datasets from a local dataset\n",
    "\n",
    "\tdata_dir = pathlib.Path(file_path)\n",
    "\tprint('Number of JPEG in dataset:',len(list(data_dir.glob('*/*.jpg')))) #print the total amount of images\n",
    "\ttrain_ds = tf.keras.preprocessing.image_dataset_from_directory(\n",
    "\t\tdata_dir,\n",
    "\t\tvalidation_split = val_split, #100-val_split% used for training, val_split% for validation\n",
    "\t\tsubset=\"training\",\n",
    "\t\tseed=710,\n",
    "\t\timage_size=(height, width),\n",
    "\t\tbatch_size=batch_size)\n",
    "\n",
    "\tval_ds = tf.keras.preprocessing.image_dataset_from_directory(\n",
    "\t\tdata_dir,\n",
    "\t\tvalidation_split = val_split,\n",
    "\t\tsubset=\"validation\",\n",
    "\t\tseed=710,\n",
    "\t\timage_size=(height, width),\n",
    "\t\tbatch_size=batch_size)\n",
    "\n",
    "\tclass_names = train_ds.class_names\n",
    "\tprint('Pokemon in set:', class_names[:3], ' ... ', class_names[-3:])\n",
    "\n",
    "\treturn train_ds, val_ds"
   ]
  },
  {
   "cell_type": "markdown",
   "id": "c48dfb70",
   "metadata": {},
   "source": [
    "Configure the dataset"
   ]
  },
  {
   "cell_type": "code",
   "execution_count": 5,
   "id": "59471089",
   "metadata": {},
   "outputs": [],
   "source": [
    "def configure_ds(train_ds, val_ds):\n",
    "\tAUTOTUNE = tf.data.experimental.AUTOTUNE\n",
    "\ttrain_ds = train_ds.cache().shuffle(1000).prefetch(buffer_size=AUTOTUNE)\n",
    "\tval_ds = val_ds.cache().prefetch(buffer_size=AUTOTUNE)\n",
    "\treturn train_ds, val_ds"
   ]
  },
  {
   "cell_type": "markdown",
   "id": "e1398664",
   "metadata": {},
   "source": [
    "Create the model "
   ]
  },
  {
   "cell_type": "code",
   "execution_count": 6,
   "id": "21c2f18a",
   "metadata": {},
   "outputs": [],
   "source": [
    "def create_model(num_classes = 5, height = 180, width = 180):\n",
    "\n",
    "\t#add data augmentation for more accurate results\n",
    "\tdata_augmentation = keras.Sequential(\n",
    "\t\t[layers.experimental.preprocessing.RandomFlip(\"horizontal\",\n",
    "\t\t    input_shape=(height,width,3)),\n",
    "\t\t\tlayers.experimental.preprocessing.RandomRotation(0.1),\n",
    "\t\t\tlayers.experimental.preprocessing.RandomZoom(0.1)]\n",
    "\t\t)\n",
    "\n",
    "\tmodel = Sequential([\n",
    "\n",
    "\t\tdata_augmentation,\n",
    "\t\t#normalize model with rescaling\n",
    "\t\tlayers.experimental.preprocessing.Rescaling(1./255, input_shape=(height, width, 3)),\n",
    "\n",
    "\t\tlayers.Conv2D(16, 3, padding='same', activation='relu'),\n",
    "\t\tlayers.MaxPooling2D(),\n",
    "\t\tlayers.Conv2D(32, 3, padding='same', activation='relu'),\n",
    "\t\tlayers.MaxPooling2D(),\n",
    "\t\t#layers.Conv2D(64, 3, padding='same', activation='relu'), #uncomment for entire data set\n",
    "\t\t#layers.MaxPooling2D(), #uncomment for entire data set\n",
    "\t\tlayers.Dropout(0.15),\n",
    "\t\tlayers.Flatten(),\n",
    "\t\tlayers.Dense(128, activation='relu'), #uncomment for entire data set\n",
    "\t\tlayers.Dense(num_classes)\n",
    "\t])\n",
    "\n",
    "\t#compile the model\n",
    "\tmodel.compile(optimizer='adam',\n",
    "\t\tloss=tf.keras.losses.SparseCategoricalCrossentropy(from_logits=True),\n",
    "\t\tmetrics=['accuracy'])\n",
    "\n",
    "\treturn model"
   ]
  },
  {
   "cell_type": "markdown",
   "id": "370955ea",
   "metadata": {},
   "source": [
    "Train the model"
   ]
  },
  {
   "cell_type": "code",
   "execution_count": 7,
   "id": "67b27411",
   "metadata": {},
   "outputs": [],
   "source": [
    "def train_model(model, train_ds, val_ds, epochs= 12):\n",
    "\thistory = model.fit(\n",
    "\t\ttrain_ds,\n",
    "\t\tvalidation_data=val_ds,\n",
    "\t\tepochs=epochs\n",
    "\t\t)\n",
    "\treturn history, epochs"
   ]
  },
  {
   "cell_type": "markdown",
   "id": "9770400c",
   "metadata": {},
   "source": [
    "Create the prediction function"
   ]
  },
  {
   "cell_type": "code",
   "execution_count": 8,
   "id": "18bd32e5",
   "metadata": {},
   "outputs": [],
   "source": [
    "def make_prediction(model, picture_path, height = 180, width = 180):\n",
    "\n",
    "\timg = keras.preprocessing.image.load_img(\n",
    "    \tpicture_path, target_size=(height, width)\n",
    "\t)\n",
    "\timg_array = keras.preprocessing.image.img_to_array(img)\n",
    "\timg_array = tf.expand_dims(img_array, 0) # Create a batch\n",
    "\n",
    "\tpredictions = model.predict(img_array)\n",
    "\tscore = tf.nn.softmax(predictions[0])\n",
    "\n",
    "\tresult_string = \"Likely {} with {:.2f}% confidence.\".format(class_names[np.argmax(score)], 100 * np.max(score))\n",
    "\t\n",
    "\timg_to_print = Image.open(picture_path)\n",
    "\tdraw = ImageDraw.Draw(img_to_print)\n",
    "\tfont = ImageFont.truetype(\"arial.ttf\", 100)\n",
    "\tdraw.text((0, 0),result_string,(255,255,255),font=font)\n",
    "\timg_to_print.show()"
   ]
  },
  {
   "cell_type": "code",
   "execution_count": null,
   "id": "fba546a1",
   "metadata": {},
   "outputs": [
    {
     "name": "stderr",
     "output_type": "stream",
     "text": [
      "ERROR:root:Internal Python error in the inspect module.\n",
      "Below is the traceback from this internal error.\n",
      "\n",
      "ERROR:root:Internal Python error in the inspect module.\n",
      "Below is the traceback from this internal error.\n",
      "\n",
      "ERROR:root:Internal Python error in the inspect module.\n",
      "Below is the traceback from this internal error.\n",
      "\n"
     ]
    },
    {
     "name": "stdout",
     "output_type": "stream",
     "text": [
      "Number of JPEG in dataset: 951\n",
      "Traceback (most recent call last):\n",
      "  File \"/usr/local/Caskroom/miniconda/base/envs/tensorflow1X/lib/python3.7/site-packages/IPython/core/interactiveshell.py\", line 3457, in run_code\n",
      "    exec(code_obj, self.user_global_ns, self.user_ns)\n",
      "  File \"/var/folders/x2/_5cxp41x5gb2t9fvqts2rph00000gn/T/ipykernel_20284/1087968663.py\", line 4, in <module>\n",
      "    train_ds, val_ds = get_local_data('dataset_popular')\n",
      "  File \"/var/folders/x2/_5cxp41x5gb2t9fvqts2rph00000gn/T/ipykernel_20284/1784240429.py\", line 6, in get_local_data\n",
      "    train_ds = tf.keras.preprocessing.image_dataset_from_directory(\n",
      "  File \"/usr/local/Caskroom/miniconda/base/envs/tensorflow1X/lib/python3.7/site-packages/tensorflow_core/python/util/module_wrapper.py\", line 193, in __getattr__\n",
      "    attr = getattr(self._tfmw_wrapped_module, name)\n",
      "AttributeError: module 'tensorflow.python.keras.api._v1.keras.preprocessing' has no attribute 'image_dataset_from_directory'\n",
      "\n",
      "During handling of the above exception, another exception occurred:\n",
      "\n",
      "Traceback (most recent call last):\n",
      "  File \"/usr/local/Caskroom/miniconda/base/envs/tensorflow1X/lib/python3.7/site-packages/IPython/core/interactiveshell.py\", line 2077, in showtraceback\n",
      "    stb = value._render_traceback_()\n",
      "AttributeError: 'AttributeError' object has no attribute '_render_traceback_'\n",
      "\n",
      "During handling of the above exception, another exception occurred:\n",
      "\n",
      "Traceback (most recent call last):\n",
      "  File \"/usr/local/Caskroom/miniconda/base/envs/tensorflow1X/lib/python3.7/site-packages/IPython/core/ultratb.py\", line 1101, in get_records\n",
      "    return _fixed_getinnerframes(etb, number_of_lines_of_context, tb_offset)\n",
      "  File \"/usr/local/Caskroom/miniconda/base/envs/tensorflow1X/lib/python3.7/site-packages/IPython/core/ultratb.py\", line 248, in wrapped\n",
      "    return f(*args, **kwargs)\n",
      "  File \"/usr/local/Caskroom/miniconda/base/envs/tensorflow1X/lib/python3.7/site-packages/IPython/core/ultratb.py\", line 281, in _fixed_getinnerframes\n",
      "    records = fix_frame_records_filenames(inspect.getinnerframes(etb, context))\n",
      "  File \"/usr/local/Caskroom/miniconda/base/envs/tensorflow1X/lib/python3.7/inspect.py\", line 1502, in getinnerframes\n",
      "    frameinfo = (tb.tb_frame,) + getframeinfo(tb, context)\n",
      "  File \"/usr/local/Caskroom/miniconda/base/envs/tensorflow1X/lib/python3.7/inspect.py\", line 1460, in getframeinfo\n",
      "    filename = getsourcefile(frame) or getfile(frame)\n",
      "  File \"/usr/local/Caskroom/miniconda/base/envs/tensorflow1X/lib/python3.7/inspect.py\", line 696, in getsourcefile\n",
      "    if getattr(getmodule(object, filename), '__loader__', None) is not None:\n",
      "  File \"/usr/local/Caskroom/miniconda/base/envs/tensorflow1X/lib/python3.7/inspect.py\", line 733, in getmodule\n",
      "    if ismodule(module) and hasattr(module, '__file__'):\n",
      "  File \"/usr/local/Caskroom/miniconda/base/envs/tensorflow1X/lib/python3.7/site-packages/tensorflow/__init__.py\", line 50, in __getattr__\n",
      "    module = self._load()\n",
      "  File \"/usr/local/Caskroom/miniconda/base/envs/tensorflow1X/lib/python3.7/site-packages/tensorflow/__init__.py\", line 44, in _load\n",
      "    module = _importlib.import_module(self.__name__)\n",
      "  File \"/usr/local/Caskroom/miniconda/base/envs/tensorflow1X/lib/python3.7/importlib/__init__.py\", line 127, in import_module\n",
      "    return _bootstrap._gcd_import(name[level:], package, level)\n",
      "  File \"<frozen importlib._bootstrap>\", line 1006, in _gcd_import\n",
      "  File \"<frozen importlib._bootstrap>\", line 983, in _find_and_load\n",
      "  File \"<frozen importlib._bootstrap>\", line 967, in _find_and_load_unlocked\n",
      "  File \"<frozen importlib._bootstrap>\", line 677, in _load_unlocked\n",
      "  File \"<frozen importlib._bootstrap_external>\", line 728, in exec_module\n",
      "  File \"<frozen importlib._bootstrap>\", line 219, in _call_with_frames_removed\n",
      "  File \"/usr/local/Caskroom/miniconda/base/envs/tensorflow1X/lib/python3.7/site-packages/tensorflow_core/contrib/__init__.py\", line 39, in <module>\n",
      "    from tensorflow.contrib import compiler\n",
      "  File \"/usr/local/Caskroom/miniconda/base/envs/tensorflow1X/lib/python3.7/site-packages/tensorflow_core/contrib/compiler/__init__.py\", line 21, in <module>\n",
      "    from tensorflow.contrib.compiler import jit\n",
      "  File \"/usr/local/Caskroom/miniconda/base/envs/tensorflow1X/lib/python3.7/site-packages/tensorflow_core/contrib/compiler/__init__.py\", line 22, in <module>\n",
      "    from tensorflow.contrib.compiler import xla\n",
      "  File \"/usr/local/Caskroom/miniconda/base/envs/tensorflow1X/lib/python3.7/site-packages/tensorflow_core/contrib/compiler/xla.py\", line 22, in <module>\n",
      "    from tensorflow.python.estimator import model_fn as model_fn_lib\n",
      "  File \"/usr/local/Caskroom/miniconda/base/envs/tensorflow1X/lib/python3.7/site-packages/tensorflow_core/python/estimator/model_fn.py\", line 26, in <module>\n",
      "    from tensorflow_estimator.python.estimator import model_fn\n",
      "  File \"/usr/local/Caskroom/miniconda/base/envs/tensorflow1X/lib/python3.7/site-packages/tensorflow_estimator/__init__.py\", line 10, in <module>\n",
      "    from tensorflow_estimator._api.v1 import estimator\n",
      "  File \"/usr/local/Caskroom/miniconda/base/envs/tensorflow1X/lib/python3.7/site-packages/tensorflow_estimator/_api/v1/estimator/__init__.py\", line 10, in <module>\n",
      "    from tensorflow_estimator._api.v1.estimator import experimental\n",
      "  File \"/usr/local/Caskroom/miniconda/base/envs/tensorflow1X/lib/python3.7/site-packages/tensorflow_estimator/_api/v1/estimator/experimental/__init__.py\", line 10, in <module>\n",
      "    from tensorflow_estimator.python.estimator.canned.dnn import dnn_logit_fn_builder\n",
      "  File \"/usr/local/Caskroom/miniconda/base/envs/tensorflow1X/lib/python3.7/site-packages/tensorflow_estimator/python/estimator/canned/dnn.py\", line 27, in <module>\n",
      "    from tensorflow_estimator.python.estimator import estimator\n",
      "  File \"/usr/local/Caskroom/miniconda/base/envs/tensorflow1X/lib/python3.7/site-packages/tensorflow_estimator/python/estimator/estimator.py\", line 36, in <module>\n",
      "    from tensorflow.python.profiler import trace\n",
      "ImportError: cannot import name 'trace' from 'tensorflow.python.profiler' (/usr/local/Caskroom/miniconda/base/envs/tensorflow1X/lib/python3.7/site-packages/tensorflow_core/python/profiler/__init__.py)\n",
      "Traceback (most recent call last):\n",
      "  File \"/usr/local/Caskroom/miniconda/base/envs/tensorflow1X/lib/python3.7/site-packages/IPython/core/interactiveshell.py\", line 3457, in run_code\n",
      "    exec(code_obj, self.user_global_ns, self.user_ns)\n",
      "  File \"/var/folders/x2/_5cxp41x5gb2t9fvqts2rph00000gn/T/ipykernel_20284/1087968663.py\", line 4, in <module>\n",
      "    train_ds, val_ds = get_local_data('dataset_popular')\n",
      "  File \"/var/folders/x2/_5cxp41x5gb2t9fvqts2rph00000gn/T/ipykernel_20284/1784240429.py\", line 6, in get_local_data\n",
      "    train_ds = tf.keras.preprocessing.image_dataset_from_directory(\n",
      "  File \"/usr/local/Caskroom/miniconda/base/envs/tensorflow1X/lib/python3.7/site-packages/tensorflow_core/python/util/module_wrapper.py\", line 193, in __getattr__\n",
      "    attr = getattr(self._tfmw_wrapped_module, name)\n",
      "AttributeError: module 'tensorflow.python.keras.api._v1.keras.preprocessing' has no attribute 'image_dataset_from_directory'\n",
      "\n",
      "During handling of the above exception, another exception occurred:\n",
      "\n",
      "Traceback (most recent call last):\n",
      "  File \"/usr/local/Caskroom/miniconda/base/envs/tensorflow1X/lib/python3.7/site-packages/IPython/core/interactiveshell.py\", line 2077, in showtraceback\n",
      "    stb = value._render_traceback_()\n",
      "AttributeError: 'AttributeError' object has no attribute '_render_traceback_'\n",
      "\n",
      "During handling of the above exception, another exception occurred:\n",
      "\n",
      "Traceback (most recent call last):\n",
      "  File \"/usr/local/Caskroom/miniconda/base/envs/tensorflow1X/lib/python3.7/site-packages/IPython/core/interactiveshell.py\", line 3377, in run_ast_nodes\n",
      "    if (await self.run_code(code, result,  async_=asy)):\n",
      "  File \"/usr/local/Caskroom/miniconda/base/envs/tensorflow1X/lib/python3.7/site-packages/IPython/core/interactiveshell.py\", line 3474, in run_code\n",
      "    self.showtraceback(running_compiled_code=True)\n",
      "  File \"/usr/local/Caskroom/miniconda/base/envs/tensorflow1X/lib/python3.7/site-packages/IPython/core/interactiveshell.py\", line 2080, in showtraceback\n",
      "    value, tb, tb_offset=tb_offset)\n",
      "  File \"/usr/local/Caskroom/miniconda/base/envs/tensorflow1X/lib/python3.7/site-packages/IPython/core/ultratb.py\", line 1368, in structured_traceback\n",
      "    self, etype, value, tb, tb_offset, number_of_lines_of_context)\n",
      "  File \"/usr/local/Caskroom/miniconda/base/envs/tensorflow1X/lib/python3.7/site-packages/IPython/core/ultratb.py\", line 1268, in structured_traceback\n",
      "    self, etype, value, tb, tb_offset, number_of_lines_of_context\n",
      "  File \"/usr/local/Caskroom/miniconda/base/envs/tensorflow1X/lib/python3.7/site-packages/IPython/core/ultratb.py\", line 1125, in structured_traceback\n",
      "    tb_offset)\n",
      "  File \"/usr/local/Caskroom/miniconda/base/envs/tensorflow1X/lib/python3.7/site-packages/IPython/core/ultratb.py\", line 1082, in format_exception_as_a_whole\n",
      "    last_unique, recursion_repeat = find_recursion(orig_etype, evalue, records)\n",
      "  File \"/usr/local/Caskroom/miniconda/base/envs/tensorflow1X/lib/python3.7/site-packages/IPython/core/ultratb.py\", line 382, in find_recursion\n",
      "    return len(records), 0\n",
      "TypeError: object of type 'NoneType' has no len()\n",
      "\n",
      "During handling of the above exception, another exception occurred:\n",
      "\n",
      "Traceback (most recent call last):\n",
      "  File \"/usr/local/Caskroom/miniconda/base/envs/tensorflow1X/lib/python3.7/site-packages/IPython/core/interactiveshell.py\", line 2077, in showtraceback\n",
      "    stb = value._render_traceback_()\n",
      "AttributeError: 'TypeError' object has no attribute '_render_traceback_'\n",
      "\n",
      "During handling of the above exception, another exception occurred:\n",
      "\n",
      "Traceback (most recent call last):\n",
      "  File \"/usr/local/Caskroom/miniconda/base/envs/tensorflow1X/lib/python3.7/site-packages/IPython/core/ultratb.py\", line 1101, in get_records\n",
      "    return _fixed_getinnerframes(etb, number_of_lines_of_context, tb_offset)\n",
      "  File \"/usr/local/Caskroom/miniconda/base/envs/tensorflow1X/lib/python3.7/site-packages/IPython/core/ultratb.py\", line 248, in wrapped\n",
      "    return f(*args, **kwargs)\n",
      "  File \"/usr/local/Caskroom/miniconda/base/envs/tensorflow1X/lib/python3.7/site-packages/IPython/core/ultratb.py\", line 281, in _fixed_getinnerframes\n",
      "    records = fix_frame_records_filenames(inspect.getinnerframes(etb, context))\n",
      "  File \"/usr/local/Caskroom/miniconda/base/envs/tensorflow1X/lib/python3.7/inspect.py\", line 1502, in getinnerframes\n",
      "    frameinfo = (tb.tb_frame,) + getframeinfo(tb, context)\n",
      "  File \"/usr/local/Caskroom/miniconda/base/envs/tensorflow1X/lib/python3.7/inspect.py\", line 1460, in getframeinfo\n",
      "    filename = getsourcefile(frame) or getfile(frame)\n",
      "  File \"/usr/local/Caskroom/miniconda/base/envs/tensorflow1X/lib/python3.7/inspect.py\", line 696, in getsourcefile\n",
      "    if getattr(getmodule(object, filename), '__loader__', None) is not None:\n",
      "  File \"/usr/local/Caskroom/miniconda/base/envs/tensorflow1X/lib/python3.7/inspect.py\", line 733, in getmodule\n",
      "    if ismodule(module) and hasattr(module, '__file__'):\n",
      "  File \"/usr/local/Caskroom/miniconda/base/envs/tensorflow1X/lib/python3.7/site-packages/tensorflow/__init__.py\", line 50, in __getattr__\n",
      "    module = self._load()\n",
      "  File \"/usr/local/Caskroom/miniconda/base/envs/tensorflow1X/lib/python3.7/site-packages/tensorflow/__init__.py\", line 44, in _load\n",
      "    module = _importlib.import_module(self.__name__)\n",
      "  File \"/usr/local/Caskroom/miniconda/base/envs/tensorflow1X/lib/python3.7/importlib/__init__.py\", line 127, in import_module\n",
      "    return _bootstrap._gcd_import(name[level:], package, level)\n",
      "  File \"<frozen importlib._bootstrap>\", line 1006, in _gcd_import\n",
      "  File \"<frozen importlib._bootstrap>\", line 983, in _find_and_load\n",
      "  File \"<frozen importlib._bootstrap>\", line 965, in _find_and_load_unlocked\n",
      "ModuleNotFoundError: No module named 'tensorflow_core.estimator'\n",
      "Traceback (most recent call last):\n",
      "  File \"/usr/local/Caskroom/miniconda/base/envs/tensorflow1X/lib/python3.7/site-packages/IPython/core/interactiveshell.py\", line 3457, in run_code\n",
      "    exec(code_obj, self.user_global_ns, self.user_ns)\n",
      "  File \"/var/folders/x2/_5cxp41x5gb2t9fvqts2rph00000gn/T/ipykernel_20284/1087968663.py\", line 4, in <module>\n",
      "    train_ds, val_ds = get_local_data('dataset_popular')\n",
      "  File \"/var/folders/x2/_5cxp41x5gb2t9fvqts2rph00000gn/T/ipykernel_20284/1784240429.py\", line 6, in get_local_data\n",
      "    train_ds = tf.keras.preprocessing.image_dataset_from_directory(\n",
      "  File \"/usr/local/Caskroom/miniconda/base/envs/tensorflow1X/lib/python3.7/site-packages/tensorflow_core/python/util/module_wrapper.py\", line 193, in __getattr__\n",
      "    attr = getattr(self._tfmw_wrapped_module, name)\n",
      "AttributeError: module 'tensorflow.python.keras.api._v1.keras.preprocessing' has no attribute 'image_dataset_from_directory'\n",
      "\n",
      "During handling of the above exception, another exception occurred:\n",
      "\n",
      "Traceback (most recent call last):\n",
      "  File \"/usr/local/Caskroom/miniconda/base/envs/tensorflow1X/lib/python3.7/site-packages/IPython/core/interactiveshell.py\", line 2077, in showtraceback\n",
      "    stb = value._render_traceback_()\n",
      "AttributeError: 'AttributeError' object has no attribute '_render_traceback_'\n",
      "\n",
      "During handling of the above exception, another exception occurred:\n",
      "\n",
      "Traceback (most recent call last):\n",
      "  File \"/usr/local/Caskroom/miniconda/base/envs/tensorflow1X/lib/python3.7/site-packages/IPython/core/interactiveshell.py\", line 3377, in run_ast_nodes\n",
      "    if (await self.run_code(code, result,  async_=asy)):\n",
      "  File \"/usr/local/Caskroom/miniconda/base/envs/tensorflow1X/lib/python3.7/site-packages/IPython/core/interactiveshell.py\", line 3474, in run_code\n",
      "    self.showtraceback(running_compiled_code=True)\n",
      "  File \"/usr/local/Caskroom/miniconda/base/envs/tensorflow1X/lib/python3.7/site-packages/IPython/core/interactiveshell.py\", line 2080, in showtraceback\n",
      "    value, tb, tb_offset=tb_offset)\n",
      "  File \"/usr/local/Caskroom/miniconda/base/envs/tensorflow1X/lib/python3.7/site-packages/IPython/core/ultratb.py\", line 1368, in structured_traceback\n",
      "    self, etype, value, tb, tb_offset, number_of_lines_of_context)\n",
      "  File \"/usr/local/Caskroom/miniconda/base/envs/tensorflow1X/lib/python3.7/site-packages/IPython/core/ultratb.py\", line 1268, in structured_traceback\n",
      "    self, etype, value, tb, tb_offset, number_of_lines_of_context\n",
      "  File \"/usr/local/Caskroom/miniconda/base/envs/tensorflow1X/lib/python3.7/site-packages/IPython/core/ultratb.py\", line 1125, in structured_traceback\n",
      "    tb_offset)\n",
      "  File \"/usr/local/Caskroom/miniconda/base/envs/tensorflow1X/lib/python3.7/site-packages/IPython/core/ultratb.py\", line 1082, in format_exception_as_a_whole\n",
      "    last_unique, recursion_repeat = find_recursion(orig_etype, evalue, records)\n",
      "  File \"/usr/local/Caskroom/miniconda/base/envs/tensorflow1X/lib/python3.7/site-packages/IPython/core/ultratb.py\", line 382, in find_recursion\n",
      "    return len(records), 0\n",
      "TypeError: object of type 'NoneType' has no len()\n",
      "\n",
      "During handling of the above exception, another exception occurred:\n",
      "\n",
      "Traceback (most recent call last):\n",
      "  File \"/usr/local/Caskroom/miniconda/base/envs/tensorflow1X/lib/python3.7/site-packages/IPython/core/interactiveshell.py\", line 2077, in showtraceback\n",
      "    stb = value._render_traceback_()\n",
      "AttributeError: 'TypeError' object has no attribute '_render_traceback_'\n",
      "\n",
      "During handling of the above exception, another exception occurred:\n",
      "\n",
      "Traceback (most recent call last):\n",
      "  File \"/usr/local/Caskroom/miniconda/base/envs/tensorflow1X/lib/python3.7/site-packages/IPython/core/interactiveshell.py\", line 2960, in _run_cell\n",
      "    return runner(coro)\n",
      "  File \"/usr/local/Caskroom/miniconda/base/envs/tensorflow1X/lib/python3.7/site-packages/IPython/core/async_helpers.py\", line 78, in _pseudo_sync_runner\n",
      "    coro.send(None)\n",
      "  File \"/usr/local/Caskroom/miniconda/base/envs/tensorflow1X/lib/python3.7/site-packages/IPython/core/interactiveshell.py\", line 3186, in run_cell_async\n",
      "    interactivity=interactivity, compiler=compiler, result=result)\n",
      "  File \"/usr/local/Caskroom/miniconda/base/envs/tensorflow1X/lib/python3.7/site-packages/IPython/core/interactiveshell.py\", line 3396, in run_ast_nodes\n",
      "    self.showtraceback()\n",
      "  File \"/usr/local/Caskroom/miniconda/base/envs/tensorflow1X/lib/python3.7/site-packages/IPython/core/interactiveshell.py\", line 2080, in showtraceback\n",
      "    value, tb, tb_offset=tb_offset)\n",
      "  File \"/usr/local/Caskroom/miniconda/base/envs/tensorflow1X/lib/python3.7/site-packages/IPython/core/ultratb.py\", line 1368, in structured_traceback\n",
      "    self, etype, value, tb, tb_offset, number_of_lines_of_context)\n",
      "  File \"/usr/local/Caskroom/miniconda/base/envs/tensorflow1X/lib/python3.7/site-packages/IPython/core/ultratb.py\", line 1268, in structured_traceback\n",
      "    self, etype, value, tb, tb_offset, number_of_lines_of_context\n",
      "  File \"/usr/local/Caskroom/miniconda/base/envs/tensorflow1X/lib/python3.7/site-packages/IPython/core/ultratb.py\", line 1143, in structured_traceback\n",
      "    chained_exceptions_tb_offset)\n",
      "  File \"/usr/local/Caskroom/miniconda/base/envs/tensorflow1X/lib/python3.7/site-packages/IPython/core/ultratb.py\", line 1082, in format_exception_as_a_whole\n",
      "    last_unique, recursion_repeat = find_recursion(orig_etype, evalue, records)\n",
      "  File \"/usr/local/Caskroom/miniconda/base/envs/tensorflow1X/lib/python3.7/site-packages/IPython/core/ultratb.py\", line 382, in find_recursion\n",
      "    return len(records), 0\n",
      "TypeError: object of type 'NoneType' has no len()\n",
      "\n",
      "During handling of the above exception, another exception occurred:\n",
      "\n",
      "Traceback (most recent call last):\n",
      "  File \"/usr/local/Caskroom/miniconda/base/envs/tensorflow1X/lib/python3.7/site-packages/IPython/core/interactiveshell.py\", line 2077, in showtraceback\n",
      "    stb = value._render_traceback_()\n",
      "AttributeError: 'TypeError' object has no attribute '_render_traceback_'\n",
      "\n",
      "During handling of the above exception, another exception occurred:\n",
      "\n",
      "Traceback (most recent call last):\n",
      "  File \"/usr/local/Caskroom/miniconda/base/envs/tensorflow1X/lib/python3.7/site-packages/IPython/core/ultratb.py\", line 1101, in get_records\n",
      "    return _fixed_getinnerframes(etb, number_of_lines_of_context, tb_offset)\n",
      "  File \"/usr/local/Caskroom/miniconda/base/envs/tensorflow1X/lib/python3.7/site-packages/IPython/core/ultratb.py\", line 248, in wrapped\n",
      "    return f(*args, **kwargs)\n",
      "  File \"/usr/local/Caskroom/miniconda/base/envs/tensorflow1X/lib/python3.7/site-packages/IPython/core/ultratb.py\", line 281, in _fixed_getinnerframes\n",
      "    records = fix_frame_records_filenames(inspect.getinnerframes(etb, context))\n",
      "  File \"/usr/local/Caskroom/miniconda/base/envs/tensorflow1X/lib/python3.7/inspect.py\", line 1502, in getinnerframes\n",
      "    frameinfo = (tb.tb_frame,) + getframeinfo(tb, context)\n",
      "  File \"/usr/local/Caskroom/miniconda/base/envs/tensorflow1X/lib/python3.7/inspect.py\", line 1460, in getframeinfo\n",
      "    filename = getsourcefile(frame) or getfile(frame)\n",
      "  File \"/usr/local/Caskroom/miniconda/base/envs/tensorflow1X/lib/python3.7/inspect.py\", line 696, in getsourcefile\n",
      "    if getattr(getmodule(object, filename), '__loader__', None) is not None:\n",
      "  File \"/usr/local/Caskroom/miniconda/base/envs/tensorflow1X/lib/python3.7/inspect.py\", line 733, in getmodule\n",
      "    if ismodule(module) and hasattr(module, '__file__'):\n",
      "  File \"/usr/local/Caskroom/miniconda/base/envs/tensorflow1X/lib/python3.7/site-packages/tensorflow/__init__.py\", line 50, in __getattr__\n",
      "    module = self._load()\n",
      "  File \"/usr/local/Caskroom/miniconda/base/envs/tensorflow1X/lib/python3.7/site-packages/tensorflow/__init__.py\", line 44, in _load\n",
      "    module = _importlib.import_module(self.__name__)\n",
      "  File \"/usr/local/Caskroom/miniconda/base/envs/tensorflow1X/lib/python3.7/importlib/__init__.py\", line 127, in import_module\n",
      "    return _bootstrap._gcd_import(name[level:], package, level)\n",
      "  File \"<frozen importlib._bootstrap>\", line 1006, in _gcd_import\n",
      "  File \"<frozen importlib._bootstrap>\", line 983, in _find_and_load\n",
      "  File \"<frozen importlib._bootstrap>\", line 965, in _find_and_load_unlocked\n",
      "ModuleNotFoundError: No module named 'tensorflow_core.estimator'\n"
     ]
    }
   ],
   "source": [
    "if __name__ == \"__main__\":\n",
    "\n",
    "\t#Retreive dataset\n",
    "\ttrain_ds, val_ds = get_local_data('dataset_popular')\n",
    "\tclass_names = train_ds.class_names\n",
    "\n",
    "\t#Train the Model\n",
    "\ttrain_ds, val_ds = configure_ds(train_ds, val_ds)\n",
    "\tmodel = create_model()\n",
    "\tprint(model.summary())\n",
    "\thistory, epochs = train_model(model, train_ds, val_ds)\n",
    "\n",
    "\t#Test the Model\n",
    "\tfor picture_path in sys.argv[1:]: make_prediction(model, picture_path = picture_path)"
   ]
  },
  {
   "cell_type": "code",
   "execution_count": null,
   "id": "bd477acb",
   "metadata": {},
   "outputs": [],
   "source": []
  }
 ],
 "metadata": {
  "kernelspec": {
   "display_name": "Python 3.7 AND tensorflow1X",
   "language": "python",
   "name": "tensorflow1x"
  },
  "language_info": {
   "codemirror_mode": {
    "name": "ipython",
    "version": 3
   },
   "file_extension": ".py",
   "mimetype": "text/x-python",
   "name": "python",
   "nbconvert_exporter": "python",
   "pygments_lexer": "ipython3",
   "version": "3.7.16"
  }
 },
 "nbformat": 4,
 "nbformat_minor": 5
}
